Workbook

Sheet Rekapitulácia stavby
A1: Export Komplet | BA1: 2.0 | BT1: False | BU1: False | BV1: {194b82ce-9e10-46a5-a605-507b1e8c3192}
AR2: >> skryté stĺpce << | BS2: 0,001 | BT2: 20
BS3: 0,001 | BT3: 20
D4: REKAPITULÁCIA STAVBY | AS4: v --- nižšie sa nachádzajú doplnkové a pomocné údaje k zostavám --- v | BE4: Návod na vyplnenie | BS4: 0,001
D5: Kód: | K5: SL20210202 | BE5: Meniť je možné iba bunky so žltým podfarbením!_x000D_ _x000D_ 1) na prvom liste Rekapitulácie stavby vyplňte v zostave_x000D_ _x000D_ a) Rekapitulácia stavby_x000D_ - údaje o Zhotoviteľovi_x000D_ (prenesú sa do ostatných zostáv aj v iných listoch)_x000D_ _x000D_ b) Rekapitulácia objektov stavby_x000D_ - potrebné Ostatné náklady_x000D_ _x000D_ 2) na vybraných listoch vyplňte v zostave_x000D_ _x000D_ a) Krycí list_x000D_ - údaje o Zhotoviteľovi, pokiaľ sa líšia od údajov o Zhotoviteľovi na Rekapitulácii stavby_x000D_ (údaje se prenesú do ostatných zostav v danom liste)_x000D_ _x000D_ b) Rekapitulácia rozpočtu_x000D_ - potrebné Ostatné náklady_x000D_ _x000D_ c) Celkové náklady za stavbu_x000D_ - ceny na položkách_x000D_ - množstvo, pokiaľ má žlté podfarbenie_x000D_ - a v prípade potreby poznámku (tá je v skrytom stĺpci) | BS5: 0,001
D6: Stavba: | K6: Most na MK v Ochodnici | BS6: 0,001
D7: JKSO: | AK7: KS: | BS7: 0,001
D8: Miesto: | K8: Ochodnica | AK8: Dátum: | AN8: 2. 2. 2021 | BS8: 0,001
BS9: 0,001
D10: Objednávateľ: | AK10: IČO: | BS10: 0,001
E11: Obec Ochodnica | AK11: IČ DPH: | BS11: 0,001
BS12: 0,001
D13: Zhotoviteľ: | AK13: IČO: | AN13: Vyplň údaj | BS13: 0,001
E14: Vyplň údaj | AK14: IČ DPH: | AN14: Vyplň údaj | BS14: 0,001
BS15: False
D16: Projektant: | AK16: IČO: | AN16: 50567004 | BS16: False
E17: TASUM, s.r.o. | AK17: IČ DPH: | AN17: SK 2120376104 | BS17: True
BS18: 0,01
D19: Spracovateľ: | AK19: IČO: | BS19: 0,01
AK20: IČ DPH: | BS20: True
D22: Poznámka:
D26: Cena bez DPH | AK26: =ROUND(AG94,2) -> 0
L28: Sadzba dane | W28: Základ dane | AK28: Výška dane
D29: DPH | F29: základná | L29: 0.2 | W29: =ROUND(AZ94, 2) -> 0 | AK29: =ROUND(AV94, 2) -> 0
F30: znížená | L30: 0.2 | W30: =ROUND(BA94, 2) -> 0 | AK30: =ROUND(AW94, 2) -> 0
F31: zákl. prenesená | L31: 0.2 | W31: =ROUND(BB94, 2) -> 0 | AK31: 0
F32: zníž. prenesená | L32: 0.2 | W32: =ROUND(BC94, 2) -> 0 | AK32: 0
F33: nulová | L33: 0 | W33: =ROUND(BD94, 2) -> 0 | AK33: 0
D35: Cena s DPH | T35: v | X35: EUR | AK35: =SUM(AK26:AK33) -> 0
D49: Projektant | AH49: Spracovateľ
D60: Dátum a podpis: | V60: Pečiatka | AH60: Dátum a podpis: | AM60: Pečiatka
D64: Objednávateľ | AH64: Zhotoviteľ
D75: Dátum a podpis: | V75: Pečiatka | AH75: Dátum a podpis: | AM75: Pečiatka
C82: REKAPITULÁCIA OBJEKTOV STAVBY
C84: Kód: | L84: =K5 -> SL20210202
C85: Stavba: | L85: =K6 -> Most na MK v Ochodnici
C87: Miesto: | L87: =IF(K8="","",K8) -> Ochodnica | AI87: Dátum: | AM87: =IF(AN8= "","",AN8) -> 2. 2. 2021
C89: Objednávateľ: | L89: =IF(E11= "","",E11) -> Obec Ochodnica | AI89: Projektant: | AM89: =IF(E17="","",E17) -> TASUM, s.r.o. | AS89: Informatívne údaje z listov zákaziek
C90: Zhotoviteľ: | L90: =IF(E14= "Vyplň údaj","",E14) | AI90: Spracovateľ: | AM90: =IF(E20="","",E20)
C92: Kód | I92: Popis | AG92: Cena bez DPH [EUR] | AN92: Cena s DPH [EUR] | AQ92: Typ | AS92: z toho Ostat._x000D_ náklady [EUR] | AT92: DPH [EUR] | AU92: Normohodiny [h] | AV92: DPH základná [EUR] | AW92: DPH znížená [EUR] | AX92: DPH základná prenesená_x000D_ [EUR] | AY92: DPH znížená prenesená_x000D_ [EUR] | AZ92: Základňa_x000D_ DPH základná | BA92: Základňa_x000D_ DPH znížená | BB92: Základňa_x000D_ DPH zákl. prenesená | BC92: Základňa_x000D_ DPH zníž. prenesená | BD92: Základňa_x000D_ DPH nulová
...

Sheet SO-1 - Rekonštrukcia most...
L2: >> skryté stĺpce << | AT2: {b4e0e101-5bd7-4522-a55e-6870f9c7a615}
AT3: 0
D4: KRYCÍ LIST ROZPOČTU | M4: v --- nižšie sa nachádzajú doplnkové a pomocné údaje k zostavám --- v | AT4: False
D6: Stavba:
E7: ='Rekapitulácia stavby'!K6 -> Most na MK v Ochodnici
D8: Objekt:
E9: SO-1 - Rekonštrukcia mosta v obci Ochodnica pri Černoškovej
D11: JKSO: | I11: KS:
D12: Miesto: | F12: Ochodnica | I12: Dátum: | J12: ='Rekapitulácia stavby'!AN8 -> 2. 2. 2021
D14: Objednávateľ: | I14: IČO:
E15: Obec Ochodnica | I15: IČ DPH:
D17: Zhotoviteľ: | I17: IČO: | J17: ='Rekapitulácia stavby'!AN13 -> Vyplň údaj
E18: ='Rekapitulácia stavby'!E14 -> Vyplň údaj | I18: IČ DPH: | J18: ='Rekapitulácia stavby'!AN14 -> Vyplň údaj
D20: Projektant: | I20: IČO: | J20: 50567004
E21: TASUM, s.r.o. | I21: IČ DPH: | J21: SK 2120376104
D23: Spracovateľ: | I23: IČO: | J23: 36421189
E24: BISin s.r.o. | I24: IČ DPH: | J24: SK2021854571
D26: Poznámka:
D30: Cena bez DPH | J30: =ROUND(J126, 2) -> 0
F32: Základ dane | I32: Sadzba dane | J32: Výška dane
D33: DPH | E33: základná | F33: =ROUND((SUM(BE126:BE236)), 2) -> 0 | I33: 0.2 | J33: =ROUND(((SUM(BE126:BE236))*I33), 2) -> 0
E34: znížená | F34: =ROUND((SUM(BF126:BF236)), 2) -> 0 | I34: 0.2 | J34: =ROUND(((SUM(BF126:BF236))*I34), 2) -> 0
E35: zákl. prenesená | F35: =ROUND((SUM(BG126:BG236)), 2) -> 0 | I35: 0.2 | J35: =0 -> 0
E36: zníž. prenesená | F36: =ROUND((SUM(BH126:BH236)), 2) -> 0 | I36: 0.2 | J36: =0 -> 0
E37: nulová | F37: =ROUND((SUM(BI126:BI236)), 2) -> 0 | I37: 0 | J37: =0 -> 0
D39: Cena s DPH | G39: v | H39: EUR | J39: =SUM(J30:J37) -> 0
D50: Projektant | G50: Spracovateľ
D61: Dátum a podpis: | F61: Pečiatka | G61: Dátum a podpis: | J61: Pečiatka
D65: Objednávateľ | G65: Zhotoviteľ
D76: Dátum a podpis: | F76: Pečiatka | G76: Dátum a podpis: | J76: Pečiatka
C82: REKAPITULÁCIA ROZPOČTU
C84: Stavba:
E85: =E7 -> Most na MK v Ochodnici
C86: Objekt:
E87: =E9 -> SO-1 - Rekonštrukcia mosta v obci Ochodnica pri Černoškovej
C89: Miesto: | F89: =F12 -> Ochodnica | I89: Dátum: | J89: =IF(J12="","",J12) -> 2. 2. 2021
C91: Objednávateľ: | F91: =E15 -> Obec Ochodnica | I91: Projektant: | J91: =E21 -> TASUM, s.r.o.
C92: Zhotoviteľ: | F92: =IF(E18="","",E18) -> Vyplň údaj | I92: Spracovateľ: | J92: =E24 -> BISin s.r.o.
C94: Kód dielu - Popis | J94: Cena celkom [EUR]
C96: Náklady z rozpočtu | J96: =J126 -> 0 | AU96: -1
...
